<?xml version="1.0" encoding="utf-8"?>
<robot name="robot">

    <material name="blue">
        <color rgba="0 0 0.8 1"/>
    </material>
    <material name="black">
        <color rgba="0 0 0 1"/>
    </material>
    <material name="white">
        <color rgba="1 1 1 1"/>
    </material>

    <link name="world"/>

    <joint name="world_to_base" type="fixed">
        <parent link="world"/>
        <child link="base_link"/>
        <origin xyz="0 0 0.5"/>
    </joint>

    <link name="base_link">
        <visual>
            <geometry>
                <cylinder length="0.6" radius="0.2"/>
            </geometry>
            <material name="blue"/>
        </visual>
        <inertial>
            <origin xyz="0 0 0" rpy="0 0 0"/>
            <mass value="1"/>
            <inertia ixx="1" ixy="0" ixz="0" iyy="1" iyz="0" izz="1"/>
        </inertial>
    </link>
    <gazebo reference="base_link">
        <material>Gazebo/Blue</material>
    </gazebo>

    <link name="right_leg">
        <visual>
            <geometry>
                <box size="0.6 0.1 0.2"/>
            </geometry>
            <origin rpy="0 1.57075 0" xyz="0 0 -0.3"/>
            <material name="white"/>
        </visual>
        <inertial>
            <origin xyz="0 0 0" rpy="0 0 0"/>
            <mass value="1"/>
            <inertia ixx="1" ixy="0" ixz="0" iyy="1" iyz="0" izz="1"/>
        </inertial>
    </link>
    <gazebo reference="right_leg">
        <material>Gazebo/White</material>
    </gazebo>

    <joint name="base_to_right_leg" type="fixed">
        <parent link="base_link"/>
        <child link="right_leg"/>
        <origin xyz="0 -0.22 0.25"/>
    </joint>

    <link name="right_base">
        <visual>
            <geometry>
                <box size="0.4 0.1 0.1"/>
            </geometry>
            <material name="white"/>
        </visual>
        <inertial>
            <origin xyz="0 0 0" rpy="0 0 0"/>
            <mass value="1"/>
            <inertia ixx="1" ixy="0" ixz="0" iyy="1" iyz="0" izz="1"/>
        </inertial>
    </link>
    <gazebo reference="right_base">
        <material>Gazebo/White</material>
    </gazebo>

    <joint name="right_base_joint" type="fixed">
        <parent link="right_leg"/>
        <child link="right_base"/>
        <origin xyz="0 0 -0.6"/>
    </joint>

    <link name="right_front_wheel">
        <visual>
            <origin rpy="1.57075 0 0" xyz="0 0 0"/>
            <geometry>
                <cylinder length="0.1" radius="0.035"/>
            </geometry>
            <material name="black"/>
            <origin rpy="0 0 0" xyz="0 0 0"/>
        </visual>
        <inertial>
            <origin xyz="0 0 0" rpy="0 0 0"/>
            <mass value="1"/>
            <inertia ixx="1" ixy="0" ixz="0" iyy="1" iyz="0" izz="1"/>
        </inertial>
    </link>
    <gazebo reference="right_front_wheel">
        <material>Gazebo/Black</material>
    </gazebo>

    <joint name="right_front_wheel_joint" type="continuous">
        <axis rpy="0 0 0" xyz="0 1 0"/>
        <parent link="right_base"/>
        <child link="right_front_wheel"/>
        <origin rpy="0 0 0" xyz="0.133333333333 0 -0.085"/>
    </joint>

    <link name="right_back_wheel">
        <visual>
            <origin rpy="1.57075 0 0" xyz="0 0 0"/>
            <geometry>
                <cylinder length="0.1" radius="0.035"/>
            </geometry>
            <material name="black"/>
        </visual>
        <inertial>
            <origin xyz="0 0 0" rpy="0 0 0"/>
            <mass value="1"/>
            <inertia ixx="1" ixy="0" ixz="0" iyy="1" iyz="0" izz="1"/>
        </inertial>
    </link>
    <gazebo reference="right_back_wheel">
        <material>Gazebo/Black</material>
    </gazebo>

    <joint name="right_back_wheel_joint" type="continuous">
        <axis rpy="0 0 0" xyz="0 1 0"/>
        <parent link="right_base"/>
        <child link="right_back_wheel"/>
        <origin rpy="0 0 0" xyz="-0.133333333333 0 -0.085"/>
    </joint>

    <link name="left_leg">
        <visual>
            <geometry>
                <box size="0.6 0.1 0.2"/>
            </geometry>
            <origin rpy="0 1.57075 0" xyz="0 0 -0.3"/>
            <material name="white"/>
        </visual>
        <inertial>
            <origin xyz="0 0 0" rpy="0 0 0"/>
            <mass value="1"/>
            <inertia ixx="1" ixy="0" ixz="0" iyy="1" iyz="0" izz="1"/>
        </inertial>
    </link>
    <gazebo reference="left_leg">
        <material>Gazebo/White</material>
    </gazebo>

    <joint name="base_to_left_leg" type="fixed">
        <parent link="base_link"/>
        <child link="left_leg"/>
        <origin xyz="0 0.22 0.25"/>
    </joint>

    <link name="left_base">
        <visual>
            <geometry>
                <box size="0.4 0.1 0.1"/>
            </geometry>
            <material name="white"/>
        </visual>
        <inertial>
            <origin xyz="0 0 0" rpy="0 0 0"/>
            <mass value="1"/>
            <inertia ixx="1" ixy="0" ixz="0" iyy="1" iyz="0" izz="1"/>
        </inertial>
    </link>
    <gazebo reference="left_base">
        <material>Gazebo/White</material>
    </gazebo>

    <joint name="left_base_joint" type="fixed">
        <parent link="left_leg"/>
        <child link="left_base"/>
        <origin xyz="0 0 -0.6"/>
    </joint>

    <link name="left_front_wheel">
        <visual>
            <origin rpy="1.57075 0 0" xyz="0 0 0"/>
            <geometry>
                <cylinder length="0.1" radius="0.035"/>
            </geometry>
            <material name="black"/>
        </visual>
        <inertial>
            <origin xyz="0 0 0" rpy="0 0 0"/>
            <mass value="1"/>
            <inertia ixx="1" ixy="0" ixz="0" iyy="1" iyz="0" izz="1"/>
        </inertial>
    </link>
    <gazebo reference="left_front_wheel">
        <material>Gazebo/Black</material>
    </gazebo>

    <joint name="left_front_wheel_joint" type="continuous">
        <axis rpy="0 0 0" xyz="0 1 0"/>
        <parent link="left_base"/>
        <child link="left_front_wheel"/>
        <origin rpy="0 0 0" xyz="0.133333333333 0 -0.085"/>
    </joint>

    <link name="left_back_wheel">
        <visual>
            <origin rpy="1.57075 0 0" xyz="0 0 0"/>
            <geometry>
                <cylinder length="0.1" radius="0.035"/>
            </geometry>
            <material name="black"/>
        </visual>
        <inertial>
            <origin xyz="0 0 0" rpy="0 0 0"/>
            <mass value="1"/>
            <inertia ixx="1" ixy="0" ixz="0" iyy="1" iyz="0" izz="1"/>
        </inertial>
    </link>
    <gazebo reference="left_back_wheel">
        <material>Gazebo/Black</material>
    </gazebo>

    <joint name="left_back_wheel_joint" type="continuous">
        <axis rpy="0 0 0" xyz="0 1 0"/>
        <parent link="left_base"/>
        <child link="left_back_wheel"/>
        <origin rpy="0 0 0" xyz="-0.133333333333 0 -0.085"/>
    </joint>

    <link name="head">
        <visual>
            <geometry>
                <sphere radius="0.2"/>
            </geometry>
            <material name="white"/>
        </visual>
        <inertial>
            <origin xyz="0 0 0" rpy="0 0 0"/>
            <mass value="1"/>
            <inertia ixx="1" ixy="0" ixz="0" iyy="1" iyz="0" izz="1"/>
        </inertial>
    </link>
    <gazebo reference="right_front_wheel">
        <material>Gazebo/Black</material>
    </gazebo>

    <joint name="head_swivel" type="continuous">
        <parent link="base_link"/>
        <child link="head"/>
        <axis xyz="0 0 1"/>
        <origin xyz="0 0 0.3"/>
    </joint>

    <link name="box">
        <visual>
            <geometry>
                <box size="0.08 0.08 0.08"/>
            </geometry>
            <material name="blue"/>
        </visual>
        <inertial>
            <origin xyz="0 0 0" rpy="0 0 0"/>
            <mass value="1"/>
            <inertia ixx="1" ixy="0" ixz="0" iyy="1" iyz="0" izz="1"/>
        </inertial>
    </link>
    <gazebo reference="box">
        <material>Gazebo/Blue</material>
    </gazebo>

    <joint name="tobox" type="fixed">
        <parent link="head"/>
        <child link="box"/>
        <origin xyz="0.1814 0 0.1414"/>
    </joint>

</robot>
